Workbook

Sheet Riepilogo
B2: PIANO ORGANICO — WINTER 2026/2027
B3: Riepilogo headcount per reparto
B5: =C39 | D5: 27 | F5: =COUNTA('Schema Manning'!$C$2:$C$96)
B8: TOTALE ORGANICO | D8: REPARTI | F8: MANSIONI CENSITE
B10: Organico per reparto
B11: Reparto | C11: Headcount | D11: % sul totale | E11: Etichetta grafico
B12: Housekeeping | C12: =SUMIF('Schema Manning'!$D$2:$D$96,"HOUSEKEEPING",'Schema Manning'!$E$2:$E$96) | D12: =C12/$C$39 | E12: Housekeeping
B13: Gargantua' Cucina | C13: =SUMIF('Schema Manning'!$D$2:$D$96,"GARGANTUA' CUCINA",'Schema Manning'!$E$2:$E$96) | D13: =C13/$C$39 | E13: Gargantua' Cucina
B14: Gargantua' Sala | C14: =SUMIF('Schema Manning'!$D$2:$D$96,"GARGANTUA' SALA",'Schema Manning'!$E$2:$E$96) | D14: =C14/$C$39 | E14: Gargantua' Sala
B15: Carnevale | C15: =SUMIF('Schema Manning'!$D$2:$D$96,"CARNEVALE",'Schema Manning'!$E$2:$E$96) | D15: =C15/$C$39 | E15: Carnevale
B16: Reception | C16: =SUMIF('Schema Manning'!$D$2:$D$96,"RECEPTION",'Schema Manning'!$E$2:$E$96) | D16: =C16/$C$39 | E16: Reception
B17: Spa | C17: =SUMIF('Schema Manning'!$D$2:$D$96,"SPA",'Schema Manning'!$E$2:$E$96) | D17: =C17/$C$39 | E17: Spa
B18: Gou/Bolla Sala | C18: =SUMIF('Schema Manning'!$D$2:$D$96,"GOU/BOLLA SALA",'Schema Manning'!$E$2:$E$96) | D18: =C18/$C$39 | E18: Gou/Bolla Sala
B19: Fire Place | C19: =SUMIF('Schema Manning'!$D$2:$D$96,"FIRE PLACE",'Schema Manning'!$E$2:$E$96) | D19: =C19/$C$39 | E19: Fire Place
B20: Gou/Bolla Cucina | C20: =SUMIF('Schema Manning'!$D$2:$D$96,"GOU/BOLLA CUCINA",'Schema Manning'!$E$2:$E$96) | D20: =C20/$C$39 | E20: Gou/Bolla Cucina
B21: Life Style | C21: =SUMIF('Schema Manning'!$D$2:$D$96,"LIFE STYLE",'Schema Manning'!$E$2:$E$96) | D21: =C21/$C$39 | E21: Life Style
B22: Manutenzione | C22: =SUMIF('Schema Manning'!$D$2:$D$96,"MANUTENZIONE",'Schema Manning'!$E$2:$E$96) | D22: =C22/$C$39 | E22: Manutenzione
B23: Shuttle | C23: =SUMIF('Schema Manning'!$D$2:$D$96,"SHUTTLE",'Schema Manning'!$E$2:$E$96) | D23: =C23/$C$39 | E23: Shuttle
B24: Direzione | C24: =SUMIF('Schema Manning'!$D$2:$D$96,"DIREZIONE",'Schema Manning'!$E$2:$E$96) | D24: =C24/$C$39 | E24: Direzione
B25: Mensa | C25: =SUMIF('Schema Manning'!$D$2:$D$96,"MENSA",'Schema Manning'!$E$2:$E$96) | D25: =C25/$C$39 | E25: Mensa
B26: Economato | C26: =SUMIF('Schema Manning'!$D$2:$D$96,"ECONOMATO",'Schema Manning'!$E$2:$E$96) | D26: =C26/$C$39 | E26: Economato
B27: Internship | C27: =SUMIF('Schema Manning'!$D$2:$D$96,"INTERNSHIP",'Schema Manning'!$E$2:$E$96) | D27: =C27/$C$39 | E27: Internship
B28: Reservations | C28: =SUMIF('Schema Manning'!$D$2:$D$96,"RESERVATIONS",'Schema Manning'!$E$2:$E$96) | D28: =C28/$C$39 | E28: Reservations
B29: Accounting | C29: =SUMIF('Schema Manning'!$D$2:$D$96,"ACCOUNTING",'Schema Manning'!$E$2:$E$96) | D29: =C29/$C$39 | E29: Accounting
B30: Lavanderia | C30: =SUMIF('Schema Manning'!$D$2:$D$96,"LAVANDERIA",'Schema Manning'!$E$2:$E$96) | D30: =C30/$C$39 | E30: Lavanderia
B31: Room Service | C31: =SUMIF('Schema Manning'!$D$2:$D$96,"ROOM SERVICE",'Schema Manning'!$E$2:$E$96) | D31: =C31/$C$39 | E31: Room Service
B32: Ski Room | C32: =SUMIF('Schema Manning'!$D$2:$D$96,"SKI ROOM",'Schema Manning'!$E$2:$E$96) | D32: =C32/$C$39 | E32: Ski Room
B33: Gou/Bolla Bar | C33: =SUMIF('Schema Manning'!$D$2:$D$96,"GOU/BOLLA BAR",'Schema Manning'!$E$2:$E$96) | D33: =C33/$C$39 | E33: Gou/Bolla Bar
B34: S&M | C34: =SUMIF('Schema Manning'!$D$2:$D$96,"S&M",'Schema Manning'!$E$2:$E$96) | D34: =C34/$C$39 | E34: S&M
B35: Banqueting | C35: =SUMIF('Schema Manning'!$D$2:$D$96,"BANQUETING",'Schema Manning'!$E$2:$E$96) | D35: =C35/$C$39 | E35: Banqueting - Banqueting & Events Coordinator
B36: Bar | C36: =SUMIF('Schema Manning'!$D$2:$D$96,"BAR",'Schema Manning'!$E$2:$E$96) | D36: =C36/$C$39 | E36: Bar - Bar Manager
B37: Gargantua'/Gou Sala | C37: =SUMIF('Schema Manning'!$D$2:$D$96,"GARGANTUA'/GOU SALA",'Schema Manning'!$E$2:$E$96) | D37: =C37/$C$39 | E37: Gargantua'/Gou Sala - Restaurant Manager
B38: Hr | C38: =SUMIF('Schema Manning'!$D$2:$D$96,"HR",'Schema Manning'!$E$2:$E$96) | D38: =C38/$C$39 | E38: Hr - Hr Manager
B39: TOTALE COMPLESSIVO | C39: =SUM(C12,C13,C14,C15,C16,C17,C18,C19,C20,C21,C22,C23,C24,C25,C26,C27,C28,C29,C30,C31,C32,C33,C34,C35,C36,C37,C38) | D39: 1
B41: Nota: un reparto del tutto nuovo (non presente in questo elenco) non viene conteggiato qui né nel grafico finché non viene aggiunta la riga corrispondente — il totale in "Dettaglio Organico" resta invece sempre corretto.

Sheet Dettaglio Organico
A1: DETTAGLIO ORGANICO PER REPARTO E MANSIONE
A3: Reparto / Mansione | B3: Headcount
A4: Accounting
A5: Addetto Alla Contabilità | B5: =SUMIFS('Schema Manning'!$E$2:$E$96,'Schema Manning'!$C$2:$C$96,$D5,'Schema Manning'!$D$2:$D$96,$E5) | D5: ADDETTO ALLA CONTABILITÀ | E5: ACCOUNTING
A6: Subtotale Accounting | B6: =SUMIF('Schema Manning'!$D$2:$D$96,"ACCOUNTING",'Schema Manning'!$E$2:$E$96)
A7: Banqueting
A8: Banqueting & Events Coordinator | B8: =SUMIFS('Schema Manning'!$E$2:$E$96,'Schema Manning'!$C$2:$C$96,$D8,'Schema Manning'!$D$2:$D$96,$E8) | D8: BANQUETING & EVENTS COORDINATOR | E8: BANQUETING
A9: Subtotale Banqueting | B9: =SUMIF('Schema Manning'!$D$2:$D$96,"BANQUETING",'Schema Manning'!$E$2:$E$96)
A10: Bar
A11: Bar Manager | B11: =SUMIFS('Schema Manning'!$E$2:$E$96,'Schema Manning'!$C$2:$C$96,$D11,'Schema Manning'!$D$2:$D$96,$E11) | D11: BAR MANAGER | E11: BAR
A12: Subtotale Bar | B12: =SUMIF('Schema Manning'!$D$2:$D$96,"BAR",'Schema Manning'!$E$2:$E$96)
A13: Direzione
A14: Eam F&B | B14: =SUMIFS('Schema Manning'!$E$2:$E$96,'Schema Manning'!$C$2:$C$96,$D14,'Schema Manning'!$D$2:$D$96,$E14) | D14: EAM F&B | E14: DIREZIONE
A15: General Manager | B15: =SUMIFS('Schema Manning'!$E$2:$E$96,'Schema Manning'!$C$2:$C$96,$D15,'Schema Manning'!$D$2:$D$96,$E15) | D15: GENERAL MANAGER | E15: DIREZIONE
A16: Operations Manager | B16: =SUMIFS('Schema Manning'!$E$2:$E$96,'Schema Manning'!$C$2:$C$96,$D16,'Schema Manning'!$D$2:$D$96,$E16) | D16: OPERATIONS MANAGER | E16: DIREZIONE
A17: Pa Gm | B17: =SUMIFS('Schema Manning'!$E$2:$E$96,'Schema Manning'!$C$2:$C$96,$D17,'Schema Manning'!$D$2:$D$96,$E17) | D17: PA GM | E17: DIREZIONE
A18: Eam Rooms/Resident Manager | B18: =SUMIFS('Schema Manning'!$E$2:$E$96,'Schema Manning'!$C$2:$C$96,$D18,'Schema Manning'!$D$2:$D$96,$E18) | D18: EAM ROOMS/RESIDENT MANAGER | E18: DIREZIONE
A19: Subtotale Direzione | B19: =SUMIF('Schema Manning'!$D$2:$D$96,"DIREZIONE",'Schema Manning'!$E$2:$E$96)
A20: Economato
A21: Economo | B21: =SUMIFS('Schema Manning'!$E$2:$E$96,'Schema Manning'!$C$2:$C$96,$D21,'Schema Manning'!$D$2:$D$96,$E21) | D21: ECONOMO | E21: ECONOMATO
A22: Magazziniere | B22: =SUMIFS('Schema Manning'!$E$2:$E$96,'Schema Manning'!$C$2:$C$96,$D22,'Schema Manning'!$D$2:$D$96,$E22) | D22: MAGAZZINIERE | E22: ECONOMATO
A23: Subtotale Economato | B23: =SUMIF('Schema Manning'!$D$2:$D$96,"ECONOMATO",'Schema Manning'!$E$2:$E$96)
A24: Fire Place
A25: Barman | B25: =SUMIFS('Schema Manning'!$E$2:$E$96,'Schema Manning'!$C$2:$C$96,$D25,'Schema Manning'!$D$2:$D$96,$E25) | D25: BARMAN | E25: FIRE PLACE
A26: Comis Bar | B26: =SUMIFS('Schema Manning'!$E$2:$E$96,'Schema Manning'!$C$2:$C$96,$D26,'Schema Manning'!$D$2:$D$96,$E26) | D26: COMIS BAR | E26: FIRE PLACE
A27: Subtotale Fire Place | B27: =SUMIF('Schema Manning'!$D$2:$D$96,"FIRE PLACE",'Schema Manning'!$E$2:$E$96)
A28: Gargantua' Cucina
A29: Capo Partita Primi | B29: =SUMIFS('Schema Manning'!$E$2:$E$96,'Schema Manning'!$C$2:$C$96,$D29,'Schema Manning'!$D$2:$D$96,$E29) | D29: CAPO PARTITA PRIMI | E29: GARGANTUA' CUCINA
A30: Capo Partita Turnante | B30: =SUMIFS('Schema Manning'!$E$2:$E$96,'Schema Manning'!$C$2:$C$96,$D30,'Schema Manning'!$D$2:$D$96,$E30) | D30: CAPO PARTITA TURNANTE | E30: GARGANTUA' CUCINA
A31: Comis Di Cucina | B31: =SUMIFS('Schema Manning'!$E$2:$E$96,'Schema Manning'!$C$2:$C$96,$D31,'Schema Manning'!$D$2:$D$96,$E31) | D31: COMIS DI CUCINA | E31: GARGANTUA' CUCINA
A32: Demis Chef Di Cucina | B32: =SUMIFS('Schema Manning'!$E$2:$E$96,'Schema Manning'!$C$2:$C$96,$D32,'Schema Manning'!$D$2:$D$96,$E32) | D32: DEMIS CHEF DI CUCINA | E32: GARGANTUA' CUCINA
A33: Executive Chef | B33: =SUMIFS('Schema Manning'!$E$2:$E$96,'Schema Manning'!$C$2:$C$96,$D33,'Schema Manning'!$D$2:$D$96,$E33) | D33: EXECUTIVE CHEF | E33: GARGANTUA' CUCINA
A34: Pasticciere | B34: =SUMIFS('Schema Manning'!$E$2:$E$96,'Schema Manning'!$C$2:$C$96,$D34,'Schema Manning'!$D$2:$D$96,$E34) | D34: PASTICCIERE | E34: GARGANTUA' CUCINA
A35: Pizzaiolo | B35: =SUMIFS('Schema Manning'!$E$2:$E$96,'Schema Manning'!$C$2:$C$96,$D35,'Schema Manning'!$D$2:$D$96,$E35) | D35: PIZZAIOLO | E35: GARGANTUA' CUCINA
A36: Pizzaiolo Gastronomo | B36: =SUMIFS('Schema Manning'!$E$2:$E$96,'Schema Manning'!$C$2:$C$96,$D36,'Schema Manning'!$D$2:$D$96,$E36) | D36: PIZZAIOLO GASTRONOMO | E36: GARGANTUA' CUCINA
A37: Plonge | B37: =SUMIFS('Schema Manning'!$E$2:$E$96,'Schema Manning'!$C$2:$C$96,$D37,'Schema Manning'!$D$2:$D$96,$E37) | D37: PLONGE | E37: GARGANTUA' CUCINA
A38: Secondo Pasticciere | B38: =SUMIFS('Schema Manning'!$E$2:$E$96,'Schema Manning'!$C$2:$C$96,$D38,'Schema Manning'!$D$2:$D$96,$E38) | D38: SECONDO PASTICCIERE | E38: GARGANTUA' CUCINA
A39: Sous Chef | B39: =SUMIFS('Schema Manning'!$E$2:$E$96,'Schema Manning'!$C$2:$C$96,$D39,'Schema Manning'!$D$2:$D$96,$E39) | D39: SOUS CHEF | E39: GARGANTUA' CUCINA
A40: Addetto Alla Pulizia Cucina | B40: =SUMIFS('Schema Manning'!$E$2:$E$96,'Schema Manning'!$C$2:$C$96,$D40,'Schema Manning'!$D$2:$D$96,$E40) | D40: ADDETTO ALLA PULIZIA CUCINA | E40: GARGANTUA' CUCINA
... A44: Head Chef | B44: =SUMIFS('Schema Manning'!$E$2:$E$96,'Schema Manning'!$C$2:$C$96,$D44,'Schema Manning'!$D$2:$D$96,$E44) | D44: HEAD CHEF | E44: GARGANTUA' CUCINA
...

Sheet Schema Manning
A1: Nome | B1: Cognome | C1: Mansione | D1: Reparto | E1: Headcount
A2: TBA | B2: TBA | C2: ADDETTO ALLA CONTABILITÀ | D2: ACCOUNTING | E2: 3
A3: TBA | B3: TBA | C3: BANQUETING & EVENTS COORDINATOR | D3: BANQUETING | E3: 1
A4: TBA | B4: TBA | C4: RESERVATIONS MANAGER | D4: RESERVATIONS | E4: 1
A5: TBA | B5: TBA | C5: BAR MANAGER | D5: BAR | E5: 1
A6: TBA | B6: TBA | C6: EAM F&B | D6: DIREZIONE | E6: 1
A7: TBA | B7: TBA | C7: EAM ROOMS/RESIDENT MANAGER | D7: DIREZIONE | E7: 1
A8: TBA | B8: TBA | C8: GENERAL MANAGER | D8: DIREZIONE | E8: 1
A9: TBA | B9: TBA | C9: OPERATIONS MANAGER | D9: DIREZIONE | E9: 1
A10: TBA | B10: TBA | C10: PA GM | D10: DIREZIONE | E10: 1
A11: TBA | B11: TBA | C11: ECONOMO | D11: ECONOMATO | E11: 2
A12: TBA | B12: TBA | C12: MAGAZZINIERE | D12: ECONOMATO | E12: 2
A13: TBA | B13: TBA | C13: BARMAN | D13: FIRE PLACE | E13: 6
... A96: TBA | B96: TBA | C96: LANCIATORE DI CORIANDOLI | D96: CARNEVALE | E96: 23
